Traceback (most recent call last):
  File "/home/long/Workspace/litellm/.venv/bin/litellm", line 7, in <module>
    sys.exit(run_server())
             ^^^^^^^^^^^^
  File "/home/long/Workspace/litellm/.venv/lib/python3.12/site-packages/click/core.py", line 1462, in __call__
    return self.main(*args, **kwargs)
           ^^^^^^^^^^^^^^^^^^^^^^^^^^
  File "/home/long/Workspace/litellm/.venv/lib/python3.12/site-packages/click/core.py", line 1383, in main
    rv = self.invoke(ctx)
         ^^^^^^^^^^^^^^^^
  File "/home/long/Workspace/litellm/.venv/lib/python3.12/site-packages/click/core.py", line 1246, in invoke
    return ctx.invoke(self.callback, **ctx.params)
           ^^^^^^^^^^^^^^^^^^^^^^^^^^^^^^^^^^^^^^^
  File "/home/long/Workspace/litellm/.venv/lib/python3.12/site-packages/click/core.py", line 814, in invoke
    return callback(*args, **kwargs)
           ^^^^^^^^^^^^^^^^^^^^^^^^^
  File "/home/long/Workspace/litellm/litellm/proxy/proxy_cli.py", line 668, in run_server
    _config = asyncio.run(proxy_config.get_config(config_file_path=config))
              ^^^^^^^^^^^^^^^^^^^^^^^^^^^^^^^^^^^^^^^^^^^^^^^^^^^^^^^^^^^^^
  File "/usr/lib/python3.12/asyncio/runners.py", line 194, in run
    return runner.run(main)
           ^^^^^^^^^^^^^^^^
  File "/usr/lib/python3.12/asyncio/runners.py", line 118, in run
    return self._loop.run_until_complete(task)
           ^^^^^^^^^^^^^^^^^^^^^^^^^^^^^^^^^^^
  File "/usr/lib/python3.12/asyncio/base_events.py", line 687, in run_until_complete
    return future.result()
           ^^^^^^^^^^^^^^^
  File "/home/long/Workspace/litellm/litellm/proxy/proxy_server.py", line 1815, in get_config
    config = await self._get_config_from_file(config_file_path=config_file_path)
             ^^^^^^^^^^^^^^^^^^^^^^^^^^^^^^^^^^^^^^^^^^^^^^^^^^^^^^^^^^^^^^^^^^^
  File "/home/long/Workspace/litellm/litellm/proxy/proxy_server.py", line 1604, in _get_config_from_file
    raise Exception(f"Config file not found: {file_path}")
Exception: Config file not found: config_dev.yaml
